Workbook

Sheet Data Sheet
A1: COMPANY NAME | B1: ASIAN PAINTS LTD | E1: =IF(B2<>B3, "A NEW VERSION OF THE WORKSHEET IS AVAILABLE", "")
A2: LATEST VERSION | B2: 2.1 | E2: PLEASE DO NOT MAKE ANY CHANGES TO THIS SHEET
A3: CURRENT VERSION | B3: 2.1
A5: META
A6: Number of shares | B6: =IF(B9>0, B9/B8, 0) -> 95.919779
A7: Face Value | B7: 1
A8: Current Price | B8: 2444
A9: Market Capitalization | B9: 234427.94
A15: PROFIT & LOSS
A16: Report Date | B16: 42825 | C16: 43190 | D16: 43555 | E16: 43921 | F16: 44286 | G16: 44651 | H16: 45016 | I16: 45382 | J16: 45747 | K16: 46112
A17: Sales | B17: 15061.99 | C17: 16824.55 | D17: 19240.13 | E17: 20211.25 | F17: 21712.79 | G17: 29101.28 | H17: 34488.59 | I17: 35494.73 | J17: 33905.62 | K17: 35583.54
A18: Raw Material Cost | B18: 7452.6 | C18: 8128.17 | D18: 9974.4 | E18: 9981.99 | F18: 10425.55 | G18: 17123.25 | H18: 18985.53 | I18: 17410.84 | J18: 17504.51 | K18: 17142.01
A19: Change in Inventory | B19: 528.6 | C19: -142.13 | D19: 293.26 | E19: 239.15 | F19: 92.45 | G19: 1324.97 | H19: 309.73 | I19: -363.8 | J19: 205 | K19: -603.68
A20: Power and Fuel | B20: 106.02 | C20: 110.3 | D20: 119.63 | E20: 97.79 | F20: 86.05 | G20: 117.23 | H20: 138.29 | I20: 133.25 | J20: 148.58 | K20: 167.1
A21: Other Mfr. Exp | B21: 1662.75 | C21: 1691.68 | D21: 1862.35 | E21: 1946.12 | F21: 2068.31 | G21: 2880.45 | H21: 2916.2 | I21: 2767.18 | J21: 2687.4 | K21: 2767.11
A22: Employee Cost | B22: 1039.89 | C22: 1121.89 | D22: 1242.69 | E22: 1371.27 | F22: 1547.61 | G22: 1794.61 | H22: 2036.41 | I22: 2334.92 | J22: 2605.78 | K22: 2809.73
A23: Selling and admin | B23: 4364.04 | C23: 2254.92 | D23: 2366.87 | E23: 2311.51 | F23: 2245.69 | G23: 2941.98 | H23: 3500.84 | I23: 3811.86 | J23: 3874.94 | K23: 4112.07
A24: Other Expenses | B24: -2028.47 | C24: 171.45 | D24: 202.51 | E24: 579.95 | F24: 576.43 | G24: 765.12 | H24: 961.21 | I24: 1087.9 | J24: 1283.2 | K24: 1282.11
A25: Other Income | B25: 337.9 | C25: 336.41 | D25: 273.77 | E25: 350.1 | F25: 331.65 | G25: 295.88 | H25: 431.46 | I25: 820.96 | J25: 350.22 | K25: 727.97
A26: Depreciation | B26: 334.79 | C26: 360.47 | D26: 622.14 | E26: 780.5 | F26: 791.27 | G26: 816.36 | H26: 858.02 | I26: 853 | J26: 1026.34 | K26: 1228.85
A27: Interest | B27: 37.33 | C27: 41.47 | D27: 110.47 | E27: 102.33 | F27: 91.63 | G27: 95.41 | H27: 144.45 | I27: 205.17 | J27: 227.02 | K27: 195.41
... A31: Dividend Amount | B31: 987.98 | C31: 834.5 | D31: 1007.16 | E31: 1151.04 | F31: 1712.17 | G31: 1836.87 | H31: 2460.35 | I31: 3194.14 | J31: 2378.82 | K31: 2637.8
A40: Quarters
A41: Report Date | B41: 45382 | C41: 45473 | D41: 45565 | E41: 45657 | F41: 45747 | G41: 45838 | H41: 45930 | I41: 46022 | J41: 46112 | K41: 46203
A42: Sales | B42: 8730.76 | C42: 8969.73 | D42: 8027.54 | E42: 8549.44 | F42: 8358.91 | G42: 8938.55 | H42: 8531.27 | I42: 8867.02 | J42: 9246.7 | K42: 10541.94
A43: Expenses | B43: 7039.39 | C43: 7275.96 | D43: 6788.03 | E43: 6912.71 | F43: 6922.71 | G43: 7313.58 | H43: 7027.89 | I43: 7086.06 | J43: 7460.09 | K43: 8373.18
A44: Other Income | B44: 212.43 | C44: 192.93 | D44: 24.53 | E44: 192.82 | F44: -60.06 | G44: 229.11 | H44: 236.94 | I44: 69.14 | J44: 196.59 | K44: 279.01
A45: Depreciation | B45: 225.61 | C45: 227.7 | D45: 241.99 | E45: 255.55 | F45: 301.1 | G45: 300.87 | H45: 304.93 | I45: 313.07 | J45: 309.98 | K45: 304.19
A46: Interest | B46: 54.1 | C46: 55.38 | D46: 63.01 | E46: 55.84 | F46: 52.79 | G46: 44.5 | H46: 43.87 | I46: 47.94 | J46: 59.1 | K46: 47.83
A47: Profit before tax | B47: 1624.09 | C47: 1603.62 | D47: 959.04 | E47: 1518.16 | F47: 1022.25 | G47: 1508.71 | H47: 1391.52 | I47: 1489.09 | J47: 1614.12 | K47: 2095.75
A48: Tax | B48: 348.79 | C48: 416.83 | D48: 265.38 | E48: 389.73 | F48: 321.42 | G48: 391.66 | H48: 373.29 | I48: 415.17 | J48: 428.63 | K48: 536.3
A49: Net profit | B49: 1256.72 | C49: 1169.98 | D49: 694.64 | E49: 1110.48 | F49: 692.13 | G49: 1099.77 | H49: 993.59 | I49: 1059.87 | J49: 1172.12 | K49: 1539.25
A50: Operating Profit | B50: 1691.37 | C50: 1693.77 | D50: 1239.51 | E50: 1636.73 | F50: 1436.2 | G50: 1624.97 | H50: 1503.38 | I50: 1780.96 | J50: 1786.61 | K50: 2168.76
A55: BALANCE SHEET
A56: Report Date | B56: 42825 | C56: 43190 | D56: 43555 | E56: 43921 | F56: 44286 | G56: 44651 | H56: 45016 | I56: 45382 | J56: 45747 | K56: 46112
A57: Equity Share Capital | B57: 95.92 | C57: 95.92 | D57: 95.92 | E57: 95.92 | F57: 95.92 | G57: 95.92 | H57: 95.92 | I57: 95.92 | J57: 95.92 | K57: 95.92
A58: Reserves | B58: 7507.97 | C58: 8314.31 | D58: 9374.63 | E58: 10034.24 | F58: 12710.37 | G58: 13715.64 | H58: 15896.31 | I58: 18632.38 | J58: 19303.89 | K58: 21275.67
A59: Borrowings | B59: 560.34 | C59: 533.43 | D59: 1319.6 | E59: 1118.5 | F59: 1093.12 | G59: 1586.88 | H59: 1932.62 | I59: 2474.38 | J59: 2290.29 | K59: 3928.93
A60: Other Liabilities | B60: 4240.96 | C60: 4819.82 | D60: 5458.69 | E60: 4889.31 | F60: 6455.93 | G60: 7559.99 | H60: 7854.48 | I60: 8698.09 | J60: 8665.15 | K60: 9218.23
A61: Total | B61: 12405.19 | C61: 13763.48 | D61: 16248.84 | E61: 16137.97 | F61: 20355.34 | G61: 22958.43 | H61: 25779.33 | I61: 29900.77 | J61: 30355.25 | K61: 34518.75
...

Sheet Data>

Sheet Historical FS
B2: ="Historical Financial Statement - " &'Data Sheet'!B1 -> Historical Financial Statement - ASIAN PAINTS LTD
B3: Years | C3: ='Data Sheet'!B16 -> 42825 | D3: ='Data Sheet'!C16 -> 43190 | E3: ='Data Sheet'!D16 -> 43555 | F3: ='Data Sheet'!E16 -> 43921 | G3: ='Data Sheet'!F16 -> 44286 | H3: ='Data Sheet'!G16 -> 44651 | I3: ='Data Sheet'!H16 -> 45016 | J3: ='Data Sheet'!I16 -> 45382 | ... L3: ='Data Sheet'!K16 -> 46112
A5: # | B5: Income Statement
B6: Sales | C6: =IFERROR('Data Sheet'!B17,0) -> 15061.99 | D6: =IFERROR('Data Sheet'!C17,0) -> 16824.55 | E6: =IFERROR('Data Sheet'!D17,0) -> 19240.13 | F6: =IFERROR('Data Sheet'!E17,0) -> 20211.25 | G6: =IFERROR('Data Sheet'!F17,0) -> 21712.79 | H6: =IFERROR('Data Sheet'!G17,0) -> 29101.28 | I6: =IFERROR('Data Sheet'!H17,0) -> 34488.59 | J6: =IFERROR('Data Sheet'!I17,0) -> 35494.73 | ... L6: =IFERROR('Data Sheet'!K17,0) -> 35583.54
B7: Sales Growth | D7: =(D6/C6-1) -> 0.11702039 | E7: =(E6/D6-1) -> 0.14357472 | F7: =(F6/E6-1) -> 0.050473671 | G7: =(G6/F6-1) -> 0.074292288 | H7: =(H6/G6-1) -> 0.34028285 | I7: =(I6/H6-1) -> 0.18512278 | J7: =(J6/I6-1) -> 0.029173127 | K7: =(K6/J6-1) -> -0.044770308 | L7: =(L6/K6-1) -> 0.049487961
B9: COGS | C9: =IFERROR(SUM('Data Sheet'!B18,'Data Sheet'!B20:B22)-1*'Data Sheet'!B19,0) -> 9732.66 | D9: =IFERROR(SUM('Data Sheet'!C18,'Data Sheet'!C20:C22)-1*'Data Sheet'!C19,0) -> 11194.17 | E9: =IFERROR(SUM('Data Sheet'!D18,'Data Sheet'!D20:D22)-1*'Data Sheet'!D19,0) -> 12905.81 | F9: =IFERROR(SUM('Data Sheet'!E18,'Data Sheet'!E20:E22)-1*'Data Sheet'!E19,0) -> 13158.02 | G9: =IFERROR(SUM('Data Sheet'!F18,'Data Sheet'!F20:F22)-1*'Data Sheet'!F19,0) -> 14035.07 | H9: =IFERROR(SUM('Data Sheet'!G18,'Data Sheet'!G20:G22)-1*'Data Sheet'!G19,0) -> 20590.57 | I9: =IFERROR(SUM('Data Sheet'!H18,'Data Sheet'!H20:H22)-1*'Data Sheet'!H19,0) -> 23766.7 | J9: =IFERROR(SUM('Data Sheet'!I18,'Data Sheet'!I20:I22)-1*'Data Sheet'!I19,0) -> 23009.99 | ... L9: =IFERROR(SUM('Data Sheet'!K18,'Data Sheet'!K20:K22)-1*'Data Sheet'!K19,0) -> 23489.63
B10: COGS % Sales | C10: =C9/C6 -> 0.64617358 | D10: =D9/D6 -> 0.66534736 | E10: =E9/E6 -> 0.67077561 | F10: =F9/F6 -> 0.65102455 | G10: =G9/G6 -> 0.64639643 | H10: =H9/H6 -> 0.7075486 | I10: =I9/I6 -> 0.68911776 | J10: =J9/J6 -> 0.64826497 | ... L10: =L9/L6 -> 0.66012628
B12: Gross Profit | C12: =C6-C9 -> 5329.33 | D12: =D6-D9 -> 5630.38 | E12: =E6-E9 -> 6334.32 | F12: =F6-F9 -> 7053.23 | G12: =G6-G9 -> 7677.72 | H12: =H6-H9 -> 8510.71 | I12: =I6-I9 -> 10721.89 | J12: =J6-J9 -> 12484.74 | ... L12: =L6-L9 -> 12093.91
B13: Gross Margin | C13: =C12/C6 -> 0.35382642 | D13: =D12/D6 -> 0.33465264 | E13: =E12/E6 -> 0.32922439 | F13: =F12/F6 -> 0.34897545 | G13: =G12/G6 -> 0.35360357 | H13: =H12/H6 -> 0.2924514 | I13: =I12/I6 -> 0.31088224 | J13: =J12/J6 -> 0.35173503 | ... L13: =L12/L6 -> 0.33987372
B15: Selling & General Expenses | C15: =IFERROR(SUM('Data Sheet'!B23:B24),0) -> 2335.57 | D15: =IFERROR(SUM('Data Sheet'!C23:C24),0) -> 2426.37 | E15: =IFERROR(SUM('Data Sheet'!D23:D24),0) -> 2569.38 | F15: =IFERROR(SUM('Data Sheet'!E23:E24),0) -> 2891.46 | G15: =IFERROR(SUM('Data Sheet'!F23:F24),0) -> 2822.12 | H15: =IFERROR(SUM('Data Sheet'!G23:G24),0) -> 3707.1 | I15: =IFERROR(SUM('Data Sheet'!H23:H24),0) -> 4462.05 | J15: =IFERROR(SUM('Data Sheet'!I23:I24),0) -> 4899.76 | ... L15: =IFERROR(SUM('Data Sheet'!K23:K24),0) -> 5394.18
B16: S&G % Sales | C16: =C15/C6 -> 0.15506384 | D16: =D15/D6 -> 0.14421604 | E16: =E15/E6 -> 0.13354276 | F16: =F15/F6 -> 0.14306191 | G16: =G15/G6 -> 0.12997501 | H16: =H15/H6 -> 0.12738615 | I16: =I15/I6 -> 0.12937757 | J16: =J15/J6 -> 0.1380419 | ... L16: =L15/L6 -> 0.151592
B18: EBITDA | C18: =C12-C15 -> 2993.76 | D18: =D12-D15 -> 3204.01 | E18: =E12-E15 -> 3764.94 | F18: =F12-F15 -> 4161.77 | G18: =G12-G15 -> 4855.6 | H18: =H12-H15 -> 4803.61 | I18: =I12-I15 -> 6259.84 | J18: =J12-J15 -> 7584.98 | ... L18: =L12-L15 -> 6699.73
B19: EBITDA % Margins | C19: =C18/C6 -> 0.19876258 | D19: =D18/D6 -> 0.19043659 | E19: =E18/E6 -> 0.19568163 | F19: =F18/F6 -> 0.20591354 | G19: =G18/G6 -> 0.22362856 | H19: =H18/H6 -> 0.16506525 | I19: =I18/I6 -> 0.18150467 | J19: =J18/J6 -> 0.21369313 | ... L19: =L18/L6 -> 0.18828172
B21: Other Income | C21: =IFERROR('Data Sheet'!B25,0) -> 337.9 | D21: =IFERROR('Data Sheet'!C25,0) -> 336.41 | E21: =IFERROR('Data Sheet'!D25,0) -> 273.77 | F21: =IFERROR('Data Sheet'!E25,0) -> 350.1 | G21: =IFERROR('Data Sheet'!F25,0) -> 331.65 | H21: =IFERROR('Data Sheet'!G25,0) -> 295.88 | I21: =IFERROR('Data Sheet'!H25,0) -> 431.46 | J21: =IFERROR('Data Sheet'!I25,0) -> 820.96 | ... L21: =IFERROR('Data Sheet'!K25,0) -> 727.97
B23: Interest | C23: =IFERROR('Data Sheet'!B27,0) -> 37.33 | D23: =IFERROR('Data Sheet'!C27,0) -> 41.47 | E23: =IFERROR('Data Sheet'!D27,0) -> 110.47 | F23: =IFERROR('Data Sheet'!E27,0) -> 102.33 | G23: =IFERROR('Data Sheet'!F27,0) -> 91.63 | H23: =IFERROR('Data Sheet'!G27,0) -> 95.41 | I23: =IFERROR('Data Sheet'!H27,0) -> 144.45 | J23: =IFERROR('Data Sheet'!I27,0) -> 205.17 | ... L23: =IFERROR('Data Sheet'!K27,0) -> 195.41
B24: Interest % Sales | C24: =C23/C6 -> 0.0024784242 | D24: =D23/D6 -> 0.0024648505 | E24: =E23/E6 -> 0.0057416452 | F24: =F23/F6 -> 0.0050630218 | G24: =G23/G6 -> 0.0042200933 | H24: =H23/H6 -> 0.0032785499 | I24: =I23/I6 -> 0.0041883417 | J24: =J23/J6 -> 0.0057802947 | ... L24: =L23/L6 -> 0.005491584
B26: Depreciation | C26: =IFERROR('Data Sheet'!B26,0) -> 334.79 | D26: =IFERROR('Data Sheet'!C26,0) -> 360.47 | E26: =IFERROR('Data Sheet'!D26,0) -> 622.14 | F26: =IFERROR('Data Sheet'!E26,0) -> 780.5 | G26: =IFERROR('Data Sheet'!F26,0) -> 791.27 | H26: =IFERROR('Data Sheet'!G26,0) -> 816.36 | I26: =IFERROR('Data Sheet'!H26,0) -> 858.02 | J26: =IFERROR('Data Sheet'!I26,0) -> 853 | ... L26: =IFERROR('Data Sheet'!K26,0) -> 1228.85
B27: Depreciation % Sales | C27: =C26/C6 -> 0.022227475 | D27: =D26/D6 -> 0.021425239 | E27: =E26/E6 -> 0.03233554 | F27: =F26/F6 -> 0.038617107 | G27: =G26/G6 -> 0.036442576 | H27: =H26/H6 -> 0.028052374 | I27: =I26/I6 -> 0.024878373 | J27: =J26/J6 -> 0.024031737 | ... L27: =L26/L6 -> 0.034534226
B29: Earning Before Tax | C29: =IFERROR(C18+C21-C23-C26,0) -> 2959.54 | D29: =IFERROR(D18+D21-D23-D26,0) -> 3138.48 | E29: =IFERROR(E18+E21-E23-E26,0) -> 3306.1 | F29: =IFERROR(F18+F21-F23-F26,0) -> 3629.04 | G29: =IFERROR(G18+G21-G23-G26,0) -> 4304.35 | H29: =IFERROR(H18+H21-H23-H26,0) -> 4187.72 | I29: =IFERROR(I18+I21-I23-I26,0) -> 5688.83 | J29: =IFERROR(J18+J21-J23-J26,0) -> 7347.77 | ... L29: =IFERROR(L18+L21-L23-L26,0) -> 6003.44
B30: EBT % Sales | C30: =C29/C6 -> 0.19649064 | D30: =D29/D6 -> 0.18654169 | E30: =E29/E6 -> 0.17183356 | F30: =F29/F6 -> 0.17955545 | G30: =G29/G6 -> 0.1982403 | H30: =H29/H6 -> 0.14390157 | I30: =I29/I6 -> 0.16494818 | J30: =J29/J6 -> 0.20701017 | ... L30: =L29/L6 -> 0.16871396
B32: Tax | C32: =IFERROR('Data Sheet'!B29,0) -> 943.29 | D32: =IFERROR('Data Sheet'!C29,0) -> 1040.96 | E32: =IFERROR('Data Sheet'!D29,0) -> 1098.06 | F32: =IFERROR('Data Sheet'!E29,0) -> 854.85 | G32: =IFERROR('Data Sheet'!F29,0) -> 1097.6 | H32: =IFERROR('Data Sheet'!G29,0) -> 1102.91 | I32: =IFERROR('Data Sheet'!H29,0) -> 1493.5 | J32: =IFERROR('Data Sheet'!I29,0) -> 1790.08 | ... L32: =IFERROR('Data Sheet'!K29,0) -> 1608.75
B33: Effective Tax Rate | C33: =C32/C29 -> 0.31872859 | D33: =D32/D29 -> 0.33167648 | E33: =E32/E29 -> 0.33213151 | F33: =F32/F29 -> 0.23555816 | G33: =G32/G29 -> 0.25499785 | H33: =H32/H29 -> 0.26336766 | I33: =I32/I29 -> 0.26253201 | J33: =J32/J29 -> 0.24362221 | ... L33: =L32/L29 -> 0.26797136
B35: Net Profit | C35: =IFERROR('Data Sheet'!B30,0) -> 1939.43 | D35: =IFERROR('Data Sheet'!C30,0) -> 2038.93 | E35: =IFERROR('Data Sheet'!D30,0) -> 2155.92 | F35: =IFERROR('Data Sheet'!E30,0) -> 2705.17 | G35: =IFERROR('Data Sheet'!F30,0) -> 3139.29 | H35: =IFERROR('Data Sheet'!G30,0) -> 3030.57 | I35: =IFERROR('Data Sheet'!H30,0) -> 4106.45 | J35: =IFERROR('Data Sheet'!I30,0) -> 5460.23 | ... L35: =IFERROR('Data Sheet'!K30,0) -> 4325.35
B36: Net Margin | C36: =C35/C6 -> 0.1287632 | D36: =D35/D6 -> 0.12118779 | E36: =E35/E6 -> 0.1120533 | F36: =F35/F6 -> 0.13384476 | G36: =G35/G6 -> 0.14458252 | H36: =H35/H6 -> 0.10413872 | I36: =I35/I6 -> 0.11906691 | J36: =J35/J6 -> 0.15383213 | ... L36: =L35/L6 -> 0.1215548
B38: No. Of Equity Shares | C38: =IFERROR('Data Sheet'!B93,0) -> 95.92 | D38: =IFERROR('Data Sheet'!C93,0) -> 95.92 | E38: =IFERROR('Data Sheet'!D93,0) -> 95.92 | F38: =IFERROR('Data Sheet'!E93,0) -> 95.92 | G38: =IFERROR('Data Sheet'!F93,0) -> 95.92 | H38: =IFERROR('Data Sheet'!G93,0) -> 95.92 | I38: =IFERROR('Data Sheet'!H93,0) -> 95.92 | J38: =IFERROR('Data Sheet'!I93,0) -> 95.92 | ... L38: =IFERROR('Data Sheet'!K93,0) -> 95.92
B39: Retain Earning % | C39: =IFERROR((C35-'Data Sheet'!B31)/C35,0) -> 0.49058228 | D39: =IFERROR((D35-'Data Sheet'!C31)/D35,0) -> 0.5907167 | E39: =IFERROR((E35-'Data Sheet'!D31)/E35,0) -> 0.53283981 | F39: =IFERROR((F35-'Data Sheet'!E31)/F35,0) -> 0.57450364 | G39: =IFERROR((G35-'Data Sheet'!F31)/G35,0) -> 0.45459961 | H39: =IFERROR((H35-'Data Sheet'!G31)/H35,0) -> 0.3938863 | I39: =IFERROR((I35-'Data Sheet'!H31)/I35,0) -> 0.40085719 | J39: =IFERROR((J35-'Data Sheet'!I31)/J35,0) -> 0.41501732 | ... L39: =IFERROR((L35-'Data Sheet'!K31)/L35,0) -> 0.3901534
B41: Earning Per Share | C41: =IFERROR(C35/C38,0) -> 20.219245 | D41: =IFERROR(D35/D38,0) -> 21.256568 | E41: =IFERROR(E35/E38,0) -> 22.47623 | F41: =IFERROR(F35/F38,0) -> 28.202356 | G41: =IFERROR(G35/G38,0) -> 32.728211 | H41: =IFERROR(H35/H38,0) -> 31.594766 | I41: =IFERROR(I35/I38,0) -> 42.811197 | J41: =IFERROR(J35/J38,0) -> 56.924833 | ... L41: =IFERROR(L35/L38,0) -> 45.093307
B42: EPS Growth % | D42: =D41/C41-1 -> 0.051303734 | E42: =E41/D41-1 -> 0.057378135 | F42: =F41/E41-1 -> 0.25476363 | G42: =G41/F41-1 -> 0.1604779 | H42: =H41/G41-1 -> -0.034632035 | I42: =I41/H41-1 -> 0.35500912 | J42: =J41/I41-1 -> 0.32967161 | K42: =K41/J41-1 -> -0.32837445 | L42: =L41/K41-1 -> 0.1794597
B44: Dividend Per Share | C44: =IFERROR('Data Sheet'!B31/C38,0) -> 10.300042 | D44: =IFERROR('Data Sheet'!C31/D38,0) -> 8.6999583 | E44: =IFERROR('Data Sheet'!D31/E38,0) -> 10.5 | F44: =IFERROR('Data Sheet'!E31/F38,0) -> 12 | G44: =IFERROR('Data Sheet'!F31/G38,0) -> 17.849979 | H44: =IFERROR('Data Sheet'!G31/H38,0) -> 19.150021 | I44: =IFERROR('Data Sheet'!H31/I38,0) -> 25.650021 | J44: =IFERROR('Data Sheet'!I31/J38,0) -> 33.300042 | ... L44: =IFERROR('Data Sheet'!K31/L38,0) -> 27.5
A46: # | B46: Balance Sheet
B48: Equity Share Capital | C48: =IFERROR('Data Sheet'!B57,0) -> 95.92 | D48: =IFERROR('Data Sheet'!C57,0) -> 95.92 | E48: =IFERROR('Data Sheet'!D57,0) -> 95.92 | F48: =IFERROR('Data Sheet'!E57,0) -> 95.92 | G48: =IFERROR('Data Sheet'!F57,0) -> 95.92 | H48: =IFERROR('Data Sheet'!G57,0) -> 95.92 | I48: =IFERROR('Data Sheet'!H57,0) -> 95.92 | J48: =IFERROR('Data Sheet'!I57,0) -> 95.92 | ... L48: =IFERROR('Data Sheet'!K57,0) -> 95.92
B49: Reserves | C49: =IFERROR('Data Sheet'!B58,0) -> 7507.97 | D49: =IFERROR('Data Sheet'!C58,0) -> 8314.31 | E49: =IFERROR('Data Sheet'!D58,0) -> 9374.63 | F49: =IFERROR('Data Sheet'!E58,0) -> 10034.24 | G49: =IFERROR('Data Sheet'!F58,0) -> 12710.37 | H49: =IFERROR('Data Sheet'!G58,0) -> 13715.64 | I49: =IFERROR('Data Sheet'!H58,0) -> 15896.31 | J49: =IFERROR('Data Sheet'!I58,0) -> 18632.38 | ... L49: =IFERROR('Data Sheet'!K58,0) -> 21275.67
B50: Borrowings | C50: =IFERROR('Data Sheet'!B59,0) -> 560.34 | D50: =IFERROR('Data Sheet'!C59,0) -> 533.43 | E50: =IFERROR('Data Sheet'!D59,0) -> 1319.6 | F50: =IFERROR('Data Sheet'!E59,0) -> 1118.5 | G50: =IFERROR('Data Sheet'!F59,0) -> 1093.12 | H50: =IFERROR('Data Sheet'!G59,0) -> 1586.88 | I50: =IFERROR('Data Sheet'!H59,0) -> 1932.62 | J50: =IFERROR('Data Sheet'!I59,0) -> 2474.38 | ... L50: =IFERROR('Data Sheet'!K59,0) -> 3928.93
B51: Other Liabilities | C51: =IFERROR('Data Sheet'!B60,0) -> 4240.96 | D51: =IFERROR('Data Sheet'!C60,0) -> 4819.82 | E51: =IFERROR('Data Sheet'!D60,0) -> 5458.69 | F51: =IFERROR('Data Sheet'!E60,0) -> 4889.31 | G51: =IFERROR('Data Sheet'!F60,0) -> 6455.93 | H51: =IFERROR('Data Sheet'!G60,0) -> 7559.99 | I51: =IFERROR('Data Sheet'!H60,0) -> 7854.48 | J51: =IFERROR('Data Sheet'!I60,0) -> 8698.09 | ... L51: =IFERROR('Data Sheet'!K60,0) -> 9218.23
B52: Total Liabilities | C52: =IFERROR('Data Sheet'!B61,0) -> 12405.19 | D52: =IFERROR('Data Sheet'!C61,0) -> 13763.48 | E52: =IFERROR('Data Sheet'!D61,0) -> 16248.84 | F52: =IFERROR('Data Sheet'!E61,0) -> 16137.97 | G52: =IFERROR('Data Sheet'!F61,0) -> 20355.34 | H52: =IFERROR('Data Sheet'!G61,0) -> 22958.43 | I52: =IFERROR('Data Sheet'!H61,0) -> 25779.33 | J52: =IFERROR('Data Sheet'!I61,0) -> 29900.77 | ... L52: =IFERROR('Data Sheet'!K61,0) -> 34518.75
B54: Fixed Assets Net Block | C54: =IFERROR('Data Sheet'!B62,0) -> 3303.74 | D54: =IFERROR('Data Sheet'!C62,0) -> 3732.24 | E54: =IFERROR('Data Sheet'!D62,0) -> 6496.56 | F54: =IFERROR('Data Sheet'!E62,0) -> 6272.31 | G54: =IFERROR('Data Sheet'!F62,0) -> 5858.52 | H54: =IFERROR('Data Sheet'!G62,0) -> 5519.06 | I54: =IFERROR('Data Sheet'!H62,0) -> 5770.46 | J54: =IFERROR('Data Sheet'!I62,0) -> 7146.62 | ... L54: =IFERROR('Data Sheet'!K62,0) -> 9640.28
B55: Capital Work in Progress | C55: =IFERROR('Data Sheet'!B63,0) -> 257.54 | D55: =IFERROR('Data Sheet'!C63,0) -> 1405.11 | E55: =IFERROR('Data Sheet'!D63,0) -> 209.67 | F55: =IFERROR('Data Sheet'!E63,0) -> 140.24 | G55: =IFERROR('Data Sheet'!F63,0) -> 182.98 | H55: =IFERROR('Data Sheet'!G63,0) -> 426.43 | I55: =IFERROR('Data Sheet'!H63,0) -> 1019.59 | J55: =IFERROR('Data Sheet'!I63,0) -> 2698.37 | ... L55: =IFERROR('Data Sheet'!K63,0) -> 1848.67
B56: Investments | C56: =IFERROR('Data Sheet'!B64,0) -> 2651.99 | D56: =IFERROR('Data Sheet'!C64,0) -> 2140.7 | E56: =IFERROR('Data Sheet'!D64,0) -> 2568.58 | F56: =IFERROR('Data Sheet'!E64,0) -> 2018.85 | G56: =IFERROR('Data Sheet'!F64,0) -> 4736.8 | H56: =IFERROR('Data Sheet'!G64,0) -> 3247.53 | I56: =IFERROR('Data Sheet'!H64,0) -> 4261.71 | J56: =IFERROR('Data Sheet'!I64,0) -> 4587.92 | ... L56: =IFERROR('Data Sheet'!K64,0) -> 7061.74
B57: Other Assets | C57: =IFERROR('Data Sheet'!B65-SUM('Data Sheet'!B67:B69),0) -> 1317.17 | D57: =IFERROR('Data Sheet'!C65-SUM('Data Sheet'!C67:C69),0) -> 1691.84 | E57: =IFERROR('Data Sheet'!D65-SUM('Data Sheet'!D67:D69),0) -> 1471.96 | F57: =IFERROR('Data Sheet'!E65-SUM('Data Sheet'!E67:E69),0) -> 1738.71 | G57: =IFERROR('Data Sheet'!F65-SUM('Data Sheet'!F67:F69),0) -> 2565.52 | H57: =IFERROR('Data Sheet'!G65-SUM('Data Sheet'!G67:G69),0) -> 2876.66 | I57: =IFERROR('Data Sheet'!H65-SUM('Data Sheet'!H67:H69),0) -> 3036.17 | J57: =IFERROR('Data Sheet'!I65-SUM('Data Sheet'!I67:I69),0) -> 3571.39 | ... L57: =IFERROR('Data Sheet'!K65-SUM('Data Sheet'!K67:K69),0) -> 4688.89
B58: Total Non Current Assets | C58: =IFERROR(SUM(C54:C57),0) -> 7530.44 | D58: =IFERROR(SUM(D54:D57),0) -> 8969.89 | E58: =IFERROR(SUM(E54:E57),0) -> 10746.77 | F58: =IFERROR(SUM(F54:F57),0) -> 10170.11 | G58: =IFERROR(SUM(G54:G57),0) -> 13343.82 | H58: =IFERROR(SUM(H54:H57),0) -> 12069.68 | I58: =IFERROR(SUM(I54:I57),0) -> 14087.93 | J58: =IFERROR(SUM(J54:J57),0) -> 18004.3 | ... L58: =IFERROR(SUM(L54:L57),0) -> 23239.58
...

Sheet Ratio analysis
B2: ="Ratio Analysis- " &'Data Sheet'!B1 -> Ratio Analysis- ASIAN PAINTS LTD
B3: Years | C3: ='Data Sheet'!B16 -> 42825 | D3: ='Data Sheet'!C16 -> 43190 | E3: ='Data Sheet'!D16 -> 43555 | F3: ='Data Sheet'!E16 -> 43921 | G3: ='Data Sheet'!F16 -> 44286 | H3: ='Data Sheet'!G16 -> 44651 | I3: ='Data Sheet'!H16 -> 45016 | J3: ='Data Sheet'!I16 -> 45382 | ... L3: ='Data Sheet'!K16 -> 46112 | M3: Trend | N3: Mean | O3: Median
B5: Sales Growth | C5: - | D5: =IFERROR('Historical FS'!D7,0) -> 0.11702039 | E5: =IFERROR('Historical FS'!E7,0) -> 0.14357472 | F5: =IFERROR('Historical FS'!F7,0) -> 0.050473671 | G5: =IFERROR('Historical FS'!G7,0) -> 0.074292288 | H5: =IFERROR('Historical FS'!H7,0) -> 0.34028285 | I5: =IFERROR('Historical FS'!I7,0) -> 0.18512278 | J5: =IFERROR('Historical FS'!J7,0) -> 0.029173127 | K5: =IFERROR('Historical FS'!K7,0) -> -0.044770308 | L5: =IFERROR('Historical FS'!L7,0) -> 0.049487961 | N5: =IFERROR(AVERAGE(D5:L5),0) -> 0.10496194 | O5: =IFERROR(MEDIAN(D5:L5),0) -> 0.074292288
B6: EBITDA Growth | C6: - | D6: =IFERROR('Historical FS'!D18/'Historical FS'!C18-1,0) -> 0.070229411 | E6: =IFERROR('Historical FS'!E18/'Historical FS'!D18-1,0) -> 0.17507124 | F6: =IFERROR('Historical FS'!F18/'Historical FS'!E18-1,0) -> 0.10540141 | G6: =IFERROR('Historical FS'!G18/'Historical FS'!F18-1,0) -> 0.16671512 | H6: =IFERROR('Historical FS'!H18/'Historical FS'!G18-1,0) -> -0.010707225 | I6: =IFERROR('Historical FS'!I18/'Historical FS'!H18-1,0) -> 0.30315325 | J6: =IFERROR('Historical FS'!J18/'Historical FS'!I18-1,0) -> 0.21168912 | K6: =IFERROR('Historical FS'!K18/'Historical FS'!J18-1,0) -> -0.20814425 | L6: =IFERROR('Historical FS'!L18/'Historical FS'!K18-1,0) -> 0.11546716 | N6: =IFERROR(AVERAGE(D6:L6),0) -> 0.10320836 | O6: =IFERROR(MEDIAN(D6:L6),0) -> 0.11546716
B7: EBIT Growth | C7: - | D7: =IFERROR('Historical FS'!D29/'Historical FS'!C29-1,0) -> 0.060462099 | E7: =IFERROR('Historical FS'!E29/'Historical FS'!D29-1,0) -> 0.053408019 | F7: =IFERROR('Historical FS'!F29/'Historical FS'!E29-1,0) -> 0.097680046 | G7: =IFERROR('Historical FS'!G29/'Historical FS'!F29-1,0) -> 0.18608503 | H7: =IFERROR('Historical FS'!H29/'Historical FS'!G29-1,0) -> -0.027095845 | I7: =IFERROR('Historical FS'!I29/'Historical FS'!H29-1,0) -> 0.3584552 | J7: =IFERROR('Historical FS'!J29/'Historical FS'!I29-1,0) -> 0.29161357 | K7: =IFERROR('Historical FS'!K29/'Historical FS'!J29-1,0) -> -0.30549405 | L7: =IFERROR('Historical FS'!L29/'Historical FS'!K29-1,0) -> 0.17643693 | N7: =IFERROR(AVERAGE(D7:L7),0) -> 0.099061221 | O7: =IFERROR(MEDIAN(D7:L7),0) -> 0.097680046
B8: Net Profit Growth | C8: - | D8: =IFERROR('Historical FS'!D35/'Historical FS'!C35-1,0) -> 0.051303734 | E8: =IFERROR('Historical FS'!E35/'Historical FS'!D35-1,0) -> 0.057378135 | F8: =IFERROR('Historical FS'!F35/'Historical FS'!E35-1,0) -> 0.25476363 | G8: =IFERROR('Historical FS'!G35/'Historical FS'!F35-1,0) -> 0.1604779 | H8: =IFERROR('Historical FS'!H35/'Historical FS'!G35-1,0) -> -0.034632035 | I8: =IFERROR('Historical FS'!I35/'Historical FS'!H35-1,0) -> 0.35500912 | J8: =IFERROR('Historical FS'!J35/'Historical FS'!I35-1,0) -> 0.32967161 | K8: =IFERROR('Historical FS'!K35/'Historical FS'!J35-1,0) -> -0.32837445 | L8: =IFERROR('Historical FS'!L35/'Historical FS'!K35-1,0) -> 0.1794597 | N8: =IFERROR(AVERAGE(D8:L8),0) -> 0.11389526 | O8: =IFERROR(MEDIAN(D8:L8),0) -> 0.1604779
B9: Dividend Growth | C9: - | D9: =IFERROR('Historical FS'!D44/'Historical FS'!C44-1,0) -> -0.15534727 | E9: =IFERROR('Historical FS'!E44/'Historical FS'!D44-1,0) -> 0.20690234 | F9: =IFERROR('Historical FS'!F44/'Historical FS'!E44-1,0) -> 0.14285714 | G9: =IFERROR('Historical FS'!G44/'Historical FS'!F44-1,0) -> 0.48749826 | H9: =IFERROR('Historical FS'!H44/'Historical FS'!G44-1,0) -> 0.072831553 | I9: =IFERROR('Historical FS'!I44/'Historical FS'!H44-1,0) -> 0.33942522 | J9: =IFERROR('Historical FS'!J44/'Historical FS'!I44-1,0) -> 0.29824618 | K9: =IFERROR('Historical FS'!K44/'Historical FS'!J44-1,0) -> -0.25525494 | L9: =IFERROR('Historical FS'!L44/'Historical FS'!K44-1,0) -> 0.1088691 | N9: =IFERROR(AVERAGE(D9:L9),0) -> 0.13844751 | O9: =IFERROR(MEDIAN(D9:L9),0) -> 0.14285714
B11: Gross Margin | C11: =IFERROR('Historical FS'!C13,0) -> 0.35382642 | D11: =IFERROR('Historical FS'!D13,0) -> 0.33465264 | E11: =IFERROR('Historical FS'!E13,0) -> 0.32922439 | F11: =IFERROR('Historical FS'!F13,0) -> 0.34897545 | G11: =IFERROR('Historical FS'!G13,0) -> 0.35360357 | H11: =IFERROR('Historical FS'!H13,0) -> 0.2924514 | I11: =IFERROR('Historical FS'!I13,0) -> 0.31088224 | J11: =IFERROR('Historical FS'!J13,0) -> 0.35173503 | ... L11: =IFERROR('Historical FS'!L13,0) -> 0.33987372 | N11: =IFERROR(AVERAGE(C11:L11),0) -> 0.33445021 | O11: =IFERROR(MEDIAN(C11:L11),0) -> 0.33726318
B12: EBITDA Margin | C12: =IFERROR('Historical FS'!C19,0) -> 0.19876258 | D12: =IFERROR('Historical FS'!D19,0) -> 0.19043659 | E12: =IFERROR('Historical FS'!E19,0) -> 0.19568163 | F12: =IFERROR('Historical FS'!F19,0) -> 0.20591354 | G12: =IFERROR('Historical FS'!G19,0) -> 0.22362856 | H12: =IFERROR('Historical FS'!H19,0) -> 0.16506525 | I12: =IFERROR('Historical FS'!I19,0) -> 0.18150467 | J12: =IFERROR('Historical FS'!J19,0) -> 0.21369313 | ... L12: =IFERROR('Historical FS'!L19,0) -> 0.18828172 | N12: =IFERROR(AVERAGE(C12:L12),0) -> 0.19401126 | O12: =IFERROR(MEDIAN(C12:L12),0) -> 0.19305911
B13: EBIT Margin | C13: =IFERROR(('Historical FS'!C18-'Historical FS'!C26)/'Historical FS'!C6,0) -> 0.17653511 | D13: =IFERROR(('Historical FS'!D18-'Historical FS'!D26)/'Historical FS'!D6,0) -> 0.16901136 | E13: =IFERROR(('Historical FS'!E18-'Historical FS'!E26)/'Historical FS'!E6,0) -> 0.16334609 | F13: =IFERROR(('Historical FS'!F18-'Historical FS'!F26)/'Historical FS'!F6,0) -> 0.16729643 | G13: =IFERROR(('Historical FS'!G18-'Historical FS'!G26)/'Historical FS'!G6,0) -> 0.18718599 | H13: =IFERROR(('Historical FS'!H18-'Historical FS'!H26)/'Historical FS'!H6,0) -> 0.13701287 | I13: =IFERROR(('Historical FS'!I18-'Historical FS'!I26)/'Historical FS'!I6,0) -> 0.15662629 | J13: =IFERROR(('Historical FS'!J18-'Historical FS'!J26)/'Historical FS'!J6,0) -> 0.18966139 | ... L13: =IFERROR(('Historical FS'!L18-'Historical FS'!L26)/'Historical FS'!L6,0) -> 0.15374749 | N13: =IFERROR(AVERAGE(C13:L13),0) -> 0.16472975 | O13: =IFERROR(MEDIAN(C13:L13),0) -> 0.16532126
B14: EBT Margin | C14: =IFERROR('Historical FS'!C30,0) -> 0.19649064 | D14: =IFERROR('Historical FS'!D30,0) -> 0.18654169 | E14: =IFERROR('Historical FS'!E30,0) -> 0.17183356 | F14: =IFERROR('Historical FS'!F30,0) -> 0.17955545 | G14: =IFERROR('Historical FS'!G30,0) -> 0.1982403 | H14: =IFERROR('Historical FS'!H30,0) -> 0.14390157 | I14: =IFERROR('Historical FS'!I30,0) -> 0.16494818 | J14: =IFERROR('Historical FS'!J30,0) -> 0.20701017 | ... L14: =IFERROR('Historical FS'!L30,0) -> 0.16871396 | N14: =IFERROR(AVERAGE(C14:L14),0) -> 0.17677436 | O14: =IFERROR(MEDIAN(C14:L14),0) -> 0.1756945
B15: Net Profit Margin | C15: =IFERROR('Historical FS'!C36,0) -> 0.1287632 | D15: =IFERROR('Historical FS'!D36,0) -> 0.12118779 | E15: =IFERROR('Historical FS'!E36,0) -> 0.1120533 | F15: =IFERROR('Historical FS'!F36,0) -> 0.13384476 | G15: =IFERROR('Historical FS'!G36,0) -> 0.14458252 | H15: =IFERROR('Historical FS'!H36,0) -> 0.10413872 | I15: =IFERROR('Historical FS'!I36,0) -> 0.11906691 | J15: =IFERROR('Historical FS'!J36,0) -> 0.15383213 | ... L15: =IFERROR('Historical FS'!L36,0) -> 0.1215548 | N15: =IFERROR(AVERAGE(C15:L15),0) -> 0.12471841 | O15: =IFERROR(MEDIAN(C15:L15),0) -> 0.12137129
B17: Sales Expenses % Sales | C17: =IFERROR('Historical FS'!C16,0) -> 0.15506384 | D17: =IFERROR('Historical FS'!D16,0) -> 0.14421604 | E17: =IFERROR('Historical FS'!E16,0) -> 0.13354276 | F17: =IFERROR('Historical FS'!F16,0) -> 0.14306191 | G17: =IFERROR('Historical FS'!G16,0) -> 0.12997501 | H17: =IFERROR('Historical FS'!H16,0) -> 0.12738615 | I17: =IFERROR('Historical FS'!I16,0) -> 0.12937757 | J17: =IFERROR('Historical FS'!J16,0) -> 0.1380419 | ... L17: =IFERROR('Historical FS'!L16,0) -> 0.151592 | N17: =IFERROR(AVERAGE(C17:L17),0) -> 0.14043895 | O17: =IFERROR(MEDIAN(C17:L17),0) -> 0.1405519
B18: Depreciation % Sales | C18: =IFERROR('Historical FS'!C27,0) -> 0.022227475 | D18: =IFERROR('Historical FS'!D27,0) -> 0.021425239 | E18: =IFERROR('Historical FS'!E27,0) -> 0.03233554 | F18: =IFERROR('Historical FS'!F27,0) -> 0.038617107 | G18: =IFERROR('Historical FS'!G27,0) -> 0.036442576 | H18: =IFERROR('Historical FS'!H27,0) -> 0.028052374 | I18: =IFERROR('Historical FS'!I27,0) -> 0.024878373 | J18: =IFERROR('Historical FS'!J27,0) -> 0.024031737 | ... L18: =IFERROR('Historical FS'!L27,0) -> 0.034534226 | N18: =IFERROR(AVERAGE(C18:L18),0) -> 0.029281514 | O18: =IFERROR(MEDIAN(C18:L18),0) -> 0.029161436
B19: Operating Income % Sales | C19: =C13 -> 0.17653511 | D19: =D13 -> 0.16901136 | E19: =E13 -> 0.16334609 | F19: =F13 -> 0.16729643 | G19: =G13 -> 0.18718599 | H19: =H13 -> 0.13701287 | I19: =I13 -> 0.15662629 | J19: =J13 -> 0.18966139 | ... L19: =L13 -> 0.15374749 | N19: =IFERROR(AVERAGE(C19:L19),0) -> 0.16472975 | O19: =IFERROR(MEDIAN(C19:L19),0) -> 0.16532126
B21: Return on Capital Employed | C21: =IFERROR(('Historical FS'!C18-'Historical FS'!C26)/(SUM('Historical FS'!C48:C50)),0) -> 0.32568534 | D21: =IFERROR(('Historical FS'!D18-'Historical FS'!D26)/(SUM('Historical FS'!D48:D50)),0) -> 0.31793919 | E21: =IFERROR(('Historical FS'!E18-'Historical FS'!E26)/(SUM('Historical FS'!E48:E50)),0) -> 0.29126565 | F21: =IFERROR(('Historical FS'!F18-'Historical FS'!F26)/(SUM('Historical FS'!F48:F50)),0) -> 0.30059314 | G21: =IFERROR(('Historical FS'!G18-'Historical FS'!G26)/(SUM('Historical FS'!G48:G50)),0) -> 0.29241025 | H21: =IFERROR(('Historical FS'!H18-'Historical FS'!H26)/(SUM('Historical FS'!H48:H50)),0) -> 0.25893857 | I21: =IFERROR(('Historical FS'!I18-'Historical FS'!I26)/(SUM('Historical FS'!I48:I50)),0) -> 0.30135929 | J21: =IFERROR(('Historical FS'!J18-'Historical FS'!J26)/(SUM('Historical FS'!J48:J50)),0) -> 0.31750609 | ... L21: =IFERROR(('Historical FS'!L18-'Historical FS'!L26)/(SUM('Historical FS'!L48:L50)),0) -> 0.21623587 | N21: =IFERROR(AVERAGE(C21:L21),0) -> 0.28515252 | O21: =IFERROR(MEDIAN(C21:L21),0) -> 0.2965017
B22: Return on Equity% | C22: =IFERROR('Historical FS'!C35/SUM('Historical FS'!C48:C49),0) -> 0.25505761 | D22: =IFERROR('Historical FS'!D35/SUM('Historical FS'!D48:D49),0) -> 0.24243451 | E22: =IFERROR('Historical FS'!E35/SUM('Historical FS'!E48:E49),0) -> 0.22764465 | F22: =IFERROR('Historical FS'!F35/SUM('Historical FS'!F48:F49),0) -> 0.26704119 | G22: =IFERROR('Historical FS'!G35/SUM('Historical FS'!G48:G49),0) -> 0.24513657 | H22: =IFERROR('Historical FS'!H35/SUM('Historical FS'!H48:H49),0) -> 0.21942272 | I22: =IFERROR('Historical FS'!I35/SUM('Historical FS'!I48:I49),0) -> 0.25677782 | J22: =IFERROR('Historical FS'!J35/SUM('Historical FS'!J48:J49),0) -> 0.29154969 | ... L22: =IFERROR('Historical FS'!L35/SUM('Historical FS'!L48:L49),0) -> 0.20238784 | N22: =IFERROR(AVERAGE(C22:L22),0) -> 0.23964869 | O22: =IFERROR(MEDIAN(C22:L22),0) -> 0.24378554
B23: Retained Earnings% | C23: ='Historical FS'!C39 -> 0.49058228 | D23: ='Historical FS'!D39 -> 0.5907167 | E23: ='Historical FS'!E39 -> 0.53283981 | F23: ='Historical FS'!F39 -> 0.57450364 | G23: ='Historical FS'!G39 -> 0.45459961 | H23: ='Historical FS'!H39 -> 0.3938863 | I23: ='Historical FS'!I39 -> 0.40085719 | J23: ='Historical FS'!J39 -> 0.41501732 | ... L23: ='Historical FS'!L39 -> 0.3901534 | N23: =IFERROR(AVERAGE(C23:L23),0) -> 0.45944868 | O23: =IFERROR(MEDIAN(C23:L23),0) -> 0.43480846
B24: Self Sustained Growth Rate | C24: =IFERROR(C22*C23,0) -> 0.12512674 | D24: =IFERROR(D22*D23,0) -> 0.14321011 | E24: =IFERROR(E22*E23,0) -> 0.12129813 | F24: =IFERROR(F22*F23,0) -> 0.15341614 | G24: =IFERROR(G22*G23,0) -> 0.11143899 | H24: =IFERROR(H22*H23,0) -> 0.086427601 | I24: =IFERROR(I22*I23,0) -> 0.10293124 | J24: =IFERROR(J22*J23,0) -> 0.12099817 | ... L24: =IFERROR(L22*L23,0) -> 0.078962305 | N24: =IFERROR(AVERAGE(C24:L24),0) -> 0.1110223 | O24: =IFERROR(MEDIAN(C24:L24),0) -> 0.11621858
B25: Interest Coverage Ratio | C25: =IFERROR(('Historical FS'!C18-'Historical FS'!C26)/'Historical FS'!C23,0) -> 71.22877 | D25: =IFERROR(('Historical FS'!D18-'Historical FS'!D26)/'Historical FS'!D23,0) -> 68.568604 | E25: =IFERROR(('Historical FS'!E18-'Historical FS'!E26)/'Historical FS'!E23,0) -> 28.449353 | F25: =IFERROR(('Historical FS'!F18-'Historical FS'!F26)/'Historical FS'!F23,0) -> 33.042803 | G25: =IFERROR(('Historical FS'!G18-'Historical FS'!G26)/'Historical FS'!G23,0) -> 44.355888 | H25: =IFERROR(('Historical FS'!H18-'Historical FS'!H26)/'Historical FS'!H23,0) -> 41.790693 | I25: =IFERROR(('Historical FS'!I18-'Historical FS'!I26)/'Historical FS'!I23,0) -> 37.395777 | J25: =IFERROR(('Historical FS'!J18-'Historical FS'!J26)/'Historical FS'!J23,0) -> 32.811717 | ... L25: =IFERROR(('Historical FS'!L18-'Historical FS'!L26)/'Historical FS'!L23,0) -> 27.99693 | N25: =IFERROR(AVERAGE(C25:L25),0) -> 40.757635 | O25: =IFERROR(MEDIAN(C25:L25),0) -> 35.21929
B27: Debtor Turnover Ratio | C27: =IFERROR('Historical FS'!C6/'Historical FS'!C60,0) -> 10.411994 | D27: =IFERROR('Historical FS'!D6/'Historical FS'!D60,0) -> 9.7216332 | E27: =IFERROR('Historical FS'!E6/'Historical FS'!E60,0) -> 10.087468 | F27: =IFERROR('Historical FS'!F6/'Historical FS'!F60,0) -> 11.258369 | G27: =IFERROR('Historical FS'!G6/'Historical FS'!G60,0) -> 8.344109 | H27: =IFERROR('Historical FS'!H6/'Historical FS'!H60,0) -> 7.5169136 | I27: =IFERROR('Historical FS'!I6/'Historical FS'!I60,0) -> 7.4377909 | J27: =IFERROR('Historical FS'!J6/'Historical FS'!J60,0) -> 7.2600464 | ... L27: =IFERROR('Historical FS'!L6/'Historical FS'!L60,0) -> 7.9751535 | N27: =IFERROR(AVERAGE(C27:L27),0) -> 8.7873554 | O27: =IFERROR(MEDIAN(C27:L27),0) -> 8.1596312
B28: Creditor Turnover Ratio | C28: =IFERROR('Historical FS'!C9/'Historical FS'!C51,0) -> 2.2949191 | D28: =IFERROR('Historical FS'!D9/'Historical FS'!D51,0) -> 2.3225286 | E28: =IFERROR('Historical FS'!E9/'Historical FS'!E51,0) -> 2.3642687 | F28: =IFERROR('Historical FS'!F9/'Historical FS'!F51,0) -> 2.6911814 | G28: =IFERROR('Historical FS'!G9/'Historical FS'!G51,0) -> 2.1739811 | H28: =IFERROR('Historical FS'!H9/'Historical FS'!H51,0) -> 2.723624 | I28: =IFERROR('Historical FS'!I9/'Historical FS'!I51,0) -> 3.0258782 | J28: =IFERROR('Historical FS'!J9/'Historical FS'!J51,0) -> 2.6454072 | ... L28: =IFERROR('Historical FS'!L9/'Historical FS'!L51,0) -> 2.5481714 | N28: =IFERROR(AVERAGE(C28:L28),0) -> 2.5414412 | O28: =IFERROR(MEDIAN(C28:L28),0) -> 2.5863117
B29: Inventory Turnover | C29: =IFERROR('Historical FS'!C9/'Historical FS'!C61,0) -> 3.7049419 | D29: =IFERROR('Historical FS'!D9/'Historical FS'!D61,0) -> 4.21101 | E29: =IFERROR('Historical FS'!E9/'Historical FS'!E61,0) -> 4.0972646 | F29: =IFERROR('Historical FS'!F9/'Historical FS'!F61,0) -> 3.8816394 | G29: =IFERROR('Historical FS'!G9/'Historical FS'!G61,0) -> 3.6948007 | H29: =IFERROR('Historical FS'!H9/'Historical FS'!H61,0) -> 3.3464386 | I29: =IFERROR('Historical FS'!I9/'Historical FS'!I61,0) -> 3.8267715 | J29: =IFERROR('Historical FS'!J9/'Historical FS'!J61,0) -> 3.8845851 | ... M29: =IFERROR('Historical FS'!M9/'Historical FS'!M61,0) -> 0 | N29: =IFERROR(AVERAGE(C29:L29),0) -> 3.8121578 | O29: =IFERROR(MEDIAN(C29:L29),0) -> 3.8542054
B30: Fixed Asset Turnover | C30: =IFERROR('Historical FS'!C6/'Historical FS'!C54,0) -> 4.5590724 | D30: =IFERROR('Historical FS'!D6/'Historical FS'!D54,0) -> 4.5078961 | E30: =IFERROR('Historical FS'!E6/'Historical FS'!E54,0) -> 2.9615874 | F30: =IFERROR('Historical FS'!F6/'Historical FS'!F54,0) -> 3.2222977 | G30: =IFERROR('Historical FS'!G6/'Historical FS'!G54,0) -> 3.7061903 | H30: =IFERROR('Historical FS'!H6/'Historical FS'!H54,0) -> 5.2728689 | I30: =IFERROR('Historical FS'!I6/'Historical FS'!I54,0) -> 5.9767488 | J30: =IFERROR('Historical FS'!J6/'Historical FS'!J54,0) -> 4.9666458 | ... L30: =IFERROR('Historical FS'!L6/'Historical FS'!L54,0) -> 3.6911314 | N30: =IFERROR(AVERAGE(C30:L30),0) -> 4.2541798 | O30: =IFERROR(MEDIAN(C30:L30),0) -> 4.1070432
B31: Capital Turnover Ratio | C31: =IFERROR('Historical FS'!C6/SUM('Historical FS'!C48:C49),0) -> 1.9808269 | D31: =IFERROR('Historical FS'!D6/SUM('Historical FS'!D48:D49),0) -> 2.0004863 | E31: =IFERROR('Historical FS'!E6/SUM('Historical FS'!E48:E49),0) -> 2.0315747 | F31: =IFERROR('Historical FS'!F6/SUM('Historical FS'!F48:F49),0) -> 1.995156 | G31: =IFERROR('Historical FS'!G6/SUM('Historical FS'!G48:G49),0) -> 1.6954785 | H31: =IFERROR('Historical FS'!H6/SUM('Historical FS'!H48:H49),0) -> 2.1070234 | I31: =IFERROR('Historical FS'!I6/SUM('Historical FS'!I48:I49),0) -> 2.1565842 | J31: =IFERROR('Historical FS'!J6/SUM('Historical FS'!J48:J49),0) -> 1.8952457 | ... L31: =IFERROR('Historical FS'!L6/SUM('Historical FS'!L48:L49),0) -> 1.6649926 | N31: =IFERROR(AVERAGE(C31:L31),0) -> 1.9275098 | O31: =IFERROR(MEDIAN(C31:L31),0) -> 1.9879915
B33: Debtor Days | C33: =IFERROR(365/C27,0) -> 35.055726 | D33: =IFERROR(365/D27,0) -> 37.545132 | E33: =IFERROR(365/E27,0) -> 36.183511 | F33: =IFERROR(365/F27,0) -> 32.420325 | G33: =IFERROR(365/G27,0) -> 43.743436 | H33: =IFERROR(365/H27,0) -> 48.557163 | I33: =IFERROR(365/I27,0) -> 49.073711 | J33: =IFERROR(365/J27,0) -> 50.275161 | ... L33: =IFERROR(365/L27,0) -> 45.767144 | N33: =IFERROR(AVERAGE(C33:L33),0) -> 42.505852 | O33: =IFERROR(MEDIAN(C33:L33),0) -> 44.75529
B34: Payable Days | C34: =IFERROR(365/C28,0) -> 159.047 | D34: =IFERROR(365/D28,0) -> 157.1563 | E34: =IFERROR(365/E28,0) -> 154.38177 | F34: =IFERROR(365/F28,0) -> 135.62817 | G34: =IFERROR(365/G28,0) -> 167.89474 | H34: =IFERROR(365/H28,0) -> 134.01263 | I34: =IFERROR(365/I28,0) -> 120.62614 | J34: =IFERROR(365/J28,0) -> 137.97498 | ... L34: =IFERROR(365/L28,0) -> 143.23997 | N34: =IFERROR(AVERAGE(C34:L34),0) -> 144.90383 | O34: =IFERROR(MEDIAN(C34:L34),0) -> 141.15831
B35: Inventory Days | C35: =IFERROR(365/C29,0) -> 98.517065 | D35: =IFERROR(365/D29,0) -> 86.677543 | E35: =IFERROR(365/E29,0) -> 89.083823 | F35: =IFERROR(365/F29,0) -> 94.032434 | G35: =IFERROR(365/G29,0) -> 98.787466 | H35: =IFERROR(365/H29,0) -> 109.07118 | I35: =IFERROR(365/I29,0) -> 95.380663 | J35: =IFERROR(365/J29,0) -> 93.961129 | ... L35: =IFERROR(365/L29,0) -> 89.249888 | N35: =IFERROR(AVERAGE(C35:L35),0) -> 96.260625 | O35: =IFERROR(MEDIAN(C35:L35),0) -> 94.706549
B36: Cash Conversion Cycle(in Days) | C36: =SUM(C33,C35)-C34 -> -25.474211 | D36: =SUM(D33,D35)-D34 -> -32.933622 | E36: =SUM(E33,E35)-E34 -> -29.11444 | F36: =SUM(F33,F35)-F34 -> -9.1754087 | G36: =SUM(G33,G35)-G34 -> -25.363839 | H36: =SUM(H33,H35)-H34 -> 23.615714 | I36: =SUM(I33,I35)-I34 -> 23.828237 | J36: =SUM(J33,J35)-J34 -> 6.2613127 | ... L36: =SUM(L33,L35)-L34 -> -8.2229401 | N36: =IFERROR(AVERAGE(C36:L36),0) -> -6.1373589 | O36: =IFERROR(MEDIAN(C36:L36),0) -> -8.6991744
B38: CFO/Sales | C38: =IFERROR('Historical FS'!C71/'Historical FS'!C6,0) -> 0.10140294 | D38: =IFERROR('Historical FS'!D71/'Historical FS'!D6,0) -> 0.12561644 | E38: =IFERROR('Historical FS'!E71/'Historical FS'!E6,0) -> 0.1283536 | F38: =IFERROR('Historical FS'!F71/'Historical FS'!F6,0) -> 0.15031975 | G38: =IFERROR('Historical FS'!G71/'Historical FS'!G6,0) -> 0.16963965 | H38: =IFERROR('Historical FS'!H71/'Historical FS'!H6,0) -> 0.033898509 | I38: =IFERROR('Historical FS'!I71/'Historical FS'!I6,0) -> 0.12158891 | J38: =IFERROR('Historical FS'!J71/'Historical FS'!J6,0) -> 0.17195792 | ... L38: =IFERROR('Historical FS'!L71/'Historical FS'!L6,0) -> 0.19919828 | N38: =IFERROR(AVERAGE(C38:L38),0) -> 0.13324547 | O38: =IFERROR(MEDIAN(C38:L38),0) -> 0.12941613
B39: CFO/Total Assets | C39: =IFERROR('Historical FS'!C71/'Historical FS'!C65,0) -> 0.12312024 | D39: =IFERROR('Historical FS'!D71/'Historical FS'!D65,0) -> 0.15355419 | E39: =IFERROR('Historical FS'!E71/'Historical FS'!E65,0) -> 0.15198254 | F39: =IFERROR('Historical FS'!F71/'Historical FS'!F65,0) -> 0.18826098 | G39: =IFERROR('Historical FS'!G71/'Historical FS'!G65,0) -> 0.18095252 | H39: =IFERROR('Historical FS'!H71/'Historical FS'!H65,0) -> 0.042968531 | I39: =IFERROR('Historical FS'!I71/'Historical FS'!I65,0) -> 0.16266637 | J39: =IFERROR('Historical FS'!J71/'Historical FS'!J65,0) -> 0.20412852 | ... L39: =IFERROR('Historical FS'!L71/'Historical FS'!L65,0) -> 0.20534289 | N39: =IFERROR(AVERAGE(C39:L39),0) -> 0.15587163 | O39: =IFERROR(MEDIAN(C39:L39),0) -> 0.15811028
B40: CFO/Total Debt | C40: =IFERROR('Historical FS'!C71/'Historical FS'!C50,0) -> 2.7257201 | D40: =IFERROR('Historical FS'!D71/'Historical FS'!D50,0) -> 3.9619819 | E40: =IFERROR('Historical FS'!E71/'Historical FS'!E50,0) -> 1.8714307 | F40: =IFERROR('Historical FS'!F71/'Historical FS'!F50,0) -> 2.7162718 | G40: =IFERROR('Historical FS'!G71/'Historical FS'!G50,0) -> 3.3695752 | H40: =IFERROR('Historical FS'!H71/'Historical FS'!H50,0) -> 0.62165381 | I40: =IFERROR('Historical FS'!I71/'Historical FS'!I50,0) -> 2.1698161 | J40: =IFERROR('Historical FS'!J71/'Historical FS'!J50,0) -> 2.4667189 | ... L40: =IFERROR('Historical FS'!L71/'Historical FS'!L50,0) -> 1.8040993 | N40: =IFERROR(AVERAGE(C40:L40),0) -> 2.3638884 | O40: =IFERROR(MEDIAN(C40:L40),0) -> 2.3182675

Sheet Common Size Statement
B2: ="Common Size Income Statement"&"-"&'Data Sheet'!$B$1 -> Common Size Income Statement-ASIAN PAINTS LTD
B4: Particulars | C4: ='Data Sheet'!B16 -> 42825 | D4: ='Data Sheet'!C16 -> 43190 | E4: ='Data Sheet'!D16 -> 43555 | F4: ='Data Sheet'!E16 -> 43921 | G4: ='Data Sheet'!F16 -> 44286 | H4: ='Data Sheet'!G16 -> 44651 | I4: ='Data Sheet'!H16 -> 45016 | J4: ='Data Sheet'!I16 -> 45382 | ... L4: ='Data Sheet'!K16 -> 46112
B6: ='Data Sheet'!A17 -> Sales | C6: ='Data Sheet'!B17/'Data Sheet'!B$17 -> 1 | D6: ='Data Sheet'!C17/'Data Sheet'!C$17 -> 1 | E6: ='Data Sheet'!D17/'Data Sheet'!D$17 -> 1 | F6: ='Data Sheet'!E17/'Data Sheet'!E$17 -> 1 | G6: ='Data Sheet'!F17/'Data Sheet'!F$17 -> 1 | H6: ='Data Sheet'!G17/'Data Sheet'!G$17 -> 1 | I6: ='Data Sheet'!H17/'Data Sheet'!H$17 -> 1 | J6: ='Data Sheet'!I17/'Data Sheet'!I$17 -> 1 | ... L6: ='Data Sheet'!K17/'Data Sheet'!K$17 -> 1
B7: ='Data Sheet'!A18 -> Raw Material Cost | C7: ='Data Sheet'!B18/'Data Sheet'!B$17 -> 0.49479518 | D7: ='Data Sheet'!C18/'Data Sheet'!C$17 -> 0.48311366 | E7: ='Data Sheet'!D18/'Data Sheet'!D$17 -> 0.51841646 | F7: ='Data Sheet'!E18/'Data Sheet'!E$17 -> 0.49388286 | G7: ='Data Sheet'!F18/'Data Sheet'!F$17 -> 0.48015709 | H7: ='Data Sheet'!G18/'Data Sheet'!G$17 -> 0.58840195 | I7: ='Data Sheet'!H18/'Data Sheet'!H$17 -> 0.55048728 | J7: ='Data Sheet'!I18/'Data Sheet'!I$17 -> 0.49051902 | ... L7: ='Data Sheet'!K18/'Data Sheet'!K$17 -> 0.48173987
B8: ='Data Sheet'!A19 -> Change in Inventory | C8: ='Data Sheet'!B19/'Data Sheet'!B$17 -> 0.035094964 | D8: ='Data Sheet'!C19/'Data Sheet'!C$17 -> -0.0084477742 | E8: ='Data Sheet'!D19/'Data Sheet'!D$17 -> 0.015242101 | F8: ='Data Sheet'!E19/'Data Sheet'!E$17 -> 0.011832519 | G8: ='Data Sheet'!F19/'Data Sheet'!F$17 -> 0.0042578591 | H8: ='Data Sheet'!G19/'Data Sheet'!G$17 -> 0.045529612 | I8: ='Data Sheet'!H19/'Data Sheet'!H$17 -> 0.0089806513 | J8: ='Data Sheet'!I19/'Data Sheet'!I$17 -> -0.010249409 | ... L8: ='Data Sheet'!K19/'Data Sheet'!K$17 -> -0.016965147
B9: ='Data Sheet'!A20 -> Power and Fuel | C9: ='Data Sheet'!B20/'Data Sheet'!B$17 -> 0.0070389105 | D9: ='Data Sheet'!C20/'Data Sheet'!C$17 -> 0.006555896 | E9: ='Data Sheet'!D20/'Data Sheet'!D$17 -> 0.0062177335 | F9: ='Data Sheet'!E20/'Data Sheet'!E$17 -> 0.0048383945 | G9: ='Data Sheet'!F20/'Data Sheet'!F$17 -> 0.0039631019 | H9: ='Data Sheet'!G20/'Data Sheet'!G$17 -> 0.0040283451 | I9: ='Data Sheet'!H20/'Data Sheet'!H$17 -> 0.0040097319 | J9: ='Data Sheet'!I20/'Data Sheet'!I$17 -> 0.0037540784 | ... L9: ='Data Sheet'!K20/'Data Sheet'!K$17 -> 0.0046959915
B10: ='Data Sheet'!A21 -> Other Mfr. Exp | C10: ='Data Sheet'!B21/'Data Sheet'!B$17 -> 0.11039378 | D10: ='Data Sheet'!C21/'Data Sheet'!C$17 -> 0.10054831 | E10: ='Data Sheet'!D21/'Data Sheet'!D$17 -> 0.096795084 | F10: ='Data Sheet'!E21/'Data Sheet'!E$17 -> 0.096288948 | G10: ='Data Sheet'!F21/'Data Sheet'!F$17 -> 0.09525768 | H10: ='Data Sheet'!G21/'Data Sheet'!G$17 -> 0.098980182 | I10: ='Data Sheet'!H21/'Data Sheet'!H$17 -> 0.084555501 | J10: ='Data Sheet'!I21/'Data Sheet'!I$17 -> 0.077960306 | ... L10: ='Data Sheet'!K21/'Data Sheet'!K$17 -> 0.077763764
B11: ='Data Sheet'!A22 -> Employee Cost | C11: ='Data Sheet'!B22/'Data Sheet'!B$17 -> 0.069040678 | D11: ='Data Sheet'!C22/'Data Sheet'!C$17 -> 0.066681724 | E11: ='Data Sheet'!D22/'Data Sheet'!D$17 -> 0.064588441 | F11: ='Data Sheet'!E22/'Data Sheet'!E$17 -> 0.067846867 | G11: ='Data Sheet'!F22/'Data Sheet'!F$17 -> 0.071276423 | H11: ='Data Sheet'!G22/'Data Sheet'!G$17 -> 0.061667734 | I11: ='Data Sheet'!H22/'Data Sheet'!H$17 -> 0.059045905 | J11: ='Data Sheet'!I22/'Data Sheet'!I$17 -> 0.06578216 | ... L11: ='Data Sheet'!K22/'Data Sheet'!K$17 -> 0.078961509
B12: ='Data Sheet'!A23 -> Selling and admin | C12: ='Data Sheet'!B23/'Data Sheet'!B$17 -> 0.28973861 | D12: ='Data Sheet'!C23/'Data Sheet'!C$17 -> 0.13402558 | E12: ='Data Sheet'!D23/'Data Sheet'!D$17 -> 0.12301736 | F12: ='Data Sheet'!E23/'Data Sheet'!E$17 -> 0.11436749 | G12: ='Data Sheet'!F23/'Data Sheet'!F$17 -> 0.10342706 | H12: ='Data Sheet'!G23/'Data Sheet'!G$17 -> 0.10109452 | I12: ='Data Sheet'!H23/'Data Sheet'!H$17 -> 0.10150719 | J12: ='Data Sheet'!I23/'Data Sheet'!I$17 -> 0.10739228 | ... L12: ='Data Sheet'!K23/'Data Sheet'!K$17 -> 0.11556102
B13: ='Data Sheet'!A24 -> Other Expenses | C13: ='Data Sheet'!B24/'Data Sheet'!B$17 -> -0.13467477 | D13: ='Data Sheet'!C24/'Data Sheet'!C$17 -> 0.010190466 | E13: ='Data Sheet'!D24/'Data Sheet'!D$17 -> 0.010525397 | F13: ='Data Sheet'!E24/'Data Sheet'!E$17 -> 0.028694415 | G13: ='Data Sheet'!F24/'Data Sheet'!F$17 -> 0.026547947 | H13: ='Data Sheet'!G24/'Data Sheet'!G$17 -> 0.026291627 | I13: ='Data Sheet'!H24/'Data Sheet'!H$17 -> 0.027870377 | J13: ='Data Sheet'!I24/'Data Sheet'!I$17 -> 0.03064962 | ... L13: ='Data Sheet'!K24/'Data Sheet'!K$17 -> 0.036030985
B14: ='Data Sheet'!A25 -> Other Income | C14: ='Data Sheet'!B25/'Data Sheet'!B$17 -> 0.022433955 | D14: ='Data Sheet'!C25/'Data Sheet'!C$17 -> 0.019995186 | E14: ='Data Sheet'!D25/'Data Sheet'!D$17 -> 0.014229114 | F14: ='Data Sheet'!E25/'Data Sheet'!E$17 -> 0.017322036 | G14: ='Data Sheet'!F25/'Data Sheet'!F$17 -> 0.015274407 | H14: ='Data Sheet'!G25/'Data Sheet'!G$17 -> 0.01016725 | I14: ='Data Sheet'!H25/'Data Sheet'!H$17 -> 0.012510224 | J14: ='Data Sheet'!I25/'Data Sheet'!I$17 -> 0.023129067 | ... L14: ='Data Sheet'!K25/'Data Sheet'!K$17 -> 0.020458054
B15: ='Data Sheet'!A26 -> Depreciation | C15: ='Data Sheet'!B26/'Data Sheet'!B$17 -> 0.022227475 | D15: ='Data Sheet'!C26/'Data Sheet'!C$17 -> 0.021425239 | E15: ='Data Sheet'!D26/'Data Sheet'!D$17 -> 0.03233554 | F15: ='Data Sheet'!E26/'Data Sheet'!E$17 -> 0.038617107 | G15: ='Data Sheet'!F26/'Data Sheet'!F$17 -> 0.036442576 | H15: ='Data Sheet'!G26/'Data Sheet'!G$17 -> 0.028052374 | I15: ='Data Sheet'!H26/'Data Sheet'!H$17 -> 0.024878373 | J15: ='Data Sheet'!I26/'Data Sheet'!I$17 -> 0.024031737 | ... L15: ='Data Sheet'!K26/'Data Sheet'!K$17 -> 0.034534226
B16: ='Data Sheet'!A27 -> Interest | C16: ='Data Sheet'!B27/'Data Sheet'!B$17 -> 0.0024784242 | D16: ='Data Sheet'!C27/'Data Sheet'!C$17 -> 0.0024648505 | E16: ='Data Sheet'!D27/'Data Sheet'!D$17 -> 0.0057416452 | F16: ='Data Sheet'!E27/'Data Sheet'!E$17 -> 0.0050630218 | G16: ='Data Sheet'!F27/'Data Sheet'!F$17 -> 0.0042200933 | H16: ='Data Sheet'!G27/'Data Sheet'!G$17 -> 0.0032785499 | I16: ='Data Sheet'!H27/'Data Sheet'!H$17 -> 0.0041883417 | J16: ='Data Sheet'!I27/'Data Sheet'!I$17 -> 0.0057802947 | ... L16: ='Data Sheet'!K27/'Data Sheet'!K$17 -> 0.005491584
B17: ='Data Sheet'!A28 -> Profit before tax | C17: ='Data Sheet'!B28/'Data Sheet'!B$17 -> 0.19649064 | D17: ='Data Sheet'!C28/'Data Sheet'!C$17 -> 0.18654169 | E17: ='Data Sheet'!D28/'Data Sheet'!D$17 -> 0.17183356 | F17: ='Data Sheet'!E28/'Data Sheet'!E$17 -> 0.17955545 | G17: ='Data Sheet'!F28/'Data Sheet'!F$17 -> 0.1982403 | H17: ='Data Sheet'!G28/'Data Sheet'!G$17 -> 0.14390157 | I17: ='Data Sheet'!H28/'Data Sheet'!H$17 -> 0.16494818 | J17: ='Data Sheet'!I28/'Data Sheet'!I$17 -> 0.20701017 | ... L17: ='Data Sheet'!K28/'Data Sheet'!K$17 -> 0.16871396
... B20: ='Data Sheet'!A31 -> Dividend Amount | C20: ='Data Sheet'!B31/'Data Sheet'!B$17 -> 0.065594254 | D20: ='Data Sheet'!C31/'Data Sheet'!C$17 -> 0.049600138 | E20: ='Data Sheet'!D31/'Data Sheet'!D$17 -> 0.05234684 | F20: ='Data Sheet'!E31/'Data Sheet'!E$17 -> 0.056950461 | G20: ='Data Sheet'!F31/'Data Sheet'!F$17 -> 0.078855366 | H20: ='Data Sheet'!G31/'Data Sheet'!G$17 -> 0.063119904 | I20: ='Data Sheet'!H31/'Data Sheet'!H$17 -> 0.071338086 | J20: ='Data Sheet'!I31/'Data Sheet'!I$17 -> 0.089989134 | ... L20: ='Data Sheet'!K31/'Data Sheet'!K$17 -> 0.07412978
B22: ="Common Size Balance Sheet"&"-"&'Data Sheet'!$B$1 -> Common Size Balance Sheet-ASIAN PAINTS LTD
B24: Particulars | C24: ='Data Sheet'!B56 -> 42825 | D24: ='Data Sheet'!C56 -> 43190 | E24: ='Data Sheet'!D56 -> 43555 | F24: ='Data Sheet'!E56 -> 43921 | G24: ='Data Sheet'!F56 -> 44286 | H24: ='Data Sheet'!G56 -> 44651 | I24: ='Data Sheet'!H56 -> 45016 | J24: ='Data Sheet'!I56 -> 45382 | ... L24: ='Data Sheet'!K56 -> 46112
B26: ='Historical FS'!B48 -> Equity Share Capital | C26: =IFERROR('Historical FS'!C48/'Historical FS'!C$52,0) -> 0.0077322476 | D26: =IFERROR('Historical FS'!D48/'Historical FS'!D$52,0) -> 0.0069691677 | E26: =IFERROR('Historical FS'!E48/'Historical FS'!E$52,0) -> 0.0059031906 | F26: =IFERROR('Historical FS'!F48/'Historical FS'!F$52,0) -> 0.0059437463 | G26: =IFERROR('Historical FS'!G48/'Historical FS'!G$52,0) -> 0.004712277 | H26: =IFERROR('Historical FS'!H48/'Historical FS'!H$52,0) -> 0.004177986 | I26: =IFERROR('Historical FS'!I48/'Historical FS'!I$52,0) -> 0.0037208104 | J26: =IFERROR('Historical FS'!J48/'Historical FS'!J$52,0) -> 0.0032079441 | ... L26: =IFERROR('Historical FS'!L48/'Historical FS'!L$52,0) -> 0.0027787796
B27: ='Historical FS'!B49 -> Reserves | C27: =IFERROR('Historical FS'!C49/'Historical FS'!C$52,0) -> 0.60522813 | D27: =IFERROR('Historical FS'!D49/'Historical FS'!D$52,0) -> 0.60408487 | E27: =IFERROR('Historical FS'!E49/'Historical FS'!E$52,0) -> 0.57694149 | F27: =IFERROR('Historical FS'!F49/'Historical FS'!F$52,0) -> 0.62177833 | G27: =IFERROR('Historical FS'!G49/'Historical FS'!G$52,0) -> 0.62442435 | H27: =IFERROR('Historical FS'!H49/'Historical FS'!H$52,0) -> 0.59741193 | I27: =IFERROR('Historical FS'!I49/'Historical FS'!I$52,0) -> 0.61663007 | J27: =IFERROR('Historical FS'!J49/'Historical FS'!J$52,0) -> 0.62314047 | ... L27: =IFERROR('Historical FS'!L49/'Historical FS'!L$52,0) -> 0.61635111
B28: ='Historical FS'!B50 -> Borrowings | C28: =IFERROR('Historical FS'!C50/'Historical FS'!C$52,0) -> 0.045169804 | D28: =IFERROR('Historical FS'!D50/'Historical FS'!D$52,0) -> 0.038756913 | E28: =IFERROR('Historical FS'!E50/'Historical FS'!E$52,0) -> 0.081211951 | F28: =IFERROR('Historical FS'!F50/'Historical FS'!F$52,0) -> 0.069308593 | G28: =IFERROR('Historical FS'!G50/'Historical FS'!G$52,0) -> 0.053701879 | H28: =IFERROR('Historical FS'!H50/'Historical FS'!H$52,0) -> 0.069119709 | I28: =IFERROR('Historical FS'!I50/'Historical FS'!I$52,0) -> 0.074967813 | J28: =IFERROR('Historical FS'!J50/'Historical FS'!J$52,0) -> 0.082753053 | ... L28: =IFERROR('Historical FS'!L50/'Historical FS'!L$52,0) -> 0.11382017
B29: ='Historical FS'!B51 -> Other Liabilities | C29: =IFERROR('Historical FS'!C51/'Historical FS'!C$52,0) -> 0.34186981 | D29: =IFERROR('Historical FS'!D51/'Historical FS'!D$52,0) -> 0.35018905 | E29: =IFERROR('Historical FS'!E51/'Historical FS'!E$52,0) -> 0.33594337 | F29: =IFERROR('Historical FS'!F51/'Historical FS'!F$52,0) -> 0.30296933 | G29: =IFERROR('Historical FS'!G51/'Historical FS'!G$52,0) -> 0.31716149 | H29: =IFERROR('Historical FS'!H51/'Historical FS'!H$52,0) -> 0.32929037 | I29: =IFERROR('Historical FS'!I51/'Historical FS'!I$52,0) -> 0.30468131 | J29: =IFERROR('Historical FS'!J51/'Historical FS'!J$52,0) -> 0.29089853 | ... L29: =IFERROR('Historical FS'!L51/'Historical FS'!L$52,0) -> 0.26704994
B30: ='Historical FS'!B52 -> Total Liabilities | C30: ='Historical FS'!C52/'Historical FS'!C52 -> 1 | D30: ='Historical FS'!D52/'Historical FS'!D52 -> 1 | E30: ='Historical FS'!E52/'Historical FS'!E52 -> 1 | F30: ='Historical FS'!F52/'Historical FS'!F52 -> 1 | G30: ='Historical FS'!G52/'Historical FS'!G52 -> 1 | H30: ='Historical FS'!H52/'Historical FS'!H52 -> 1 | I30: ='Historical FS'!I52/'Historical FS'!I52 -> 1 | J30: ='Historical FS'!J52/'Historical FS'!J52 -> 1 | ... L30: ='Historical FS'!L52/'Historical FS'!L52 -> 1
B32: ='Historical FS'!B54 -> Fixed Assets Net Block | C32: =IFERROR('Historical FS'!C54/'Historical FS'!C$65,0) -> 0.26631918 | D32: =IFERROR('Historical FS'!D54/'Historical FS'!D$65,0) -> 0.27116979 | E32: =IFERROR('Historical FS'!E54/'Historical FS'!E$65,0) -> 0.39981685 | F32: =IFERROR('Historical FS'!F54/'Historical FS'!F$65,0) -> 0.38866784 | G32: =IFERROR('Historical FS'!G54/'Historical FS'!G$65,0) -> 0.28781244 | H32: =IFERROR('Historical FS'!H54/'Historical FS'!H$65,0) -> 0.24039362 | I32: =IFERROR('Historical FS'!I54/'Historical FS'!I$65,0) -> 0.22384057 | J32: =IFERROR('Historical FS'!J54/'Historical FS'!J$65,0) -> 0.23901124 | ... L32: =IFERROR('Historical FS'!L54/'Historical FS'!L$65,0) -> 0.27927663
B33: ='Historical FS'!B55 -> Capital Work in Progress | C33: =IFERROR('Historical FS'!C55/'Historical FS'!C$65,0) -> 0.020760665 | D33: =IFERROR('Historical FS'!D55/'Historical FS'!D$65,0) -> 0.10208973 | E33: =IFERROR('Historical FS'!E55/'Historical FS'!E$65,0) -> 0.01290369 | F33: =IFERROR('Historical FS'!F55/'Historical FS'!F$65,0) -> 0.0086900645 | G33: =IFERROR('Historical FS'!G55/'Historical FS'!G$65,0) -> 0.0089892873 | H33: =IFERROR('Historical FS'!H55/'Historical FS'!H$65,0) -> 0.018574005 | I33: =IFERROR('Historical FS'!I55/'Historical FS'!I$65,0) -> 0.039550679 | J33: =IFERROR('Historical FS'!J55/'Historical FS'!J$65,0) -> 0.090244164 | ... L33: =IFERROR('Historical FS'!L55/'Historical FS'!L$65,0) -> 0.053555531
B34: ='Historical FS'!B56 -> Investments | C34: =IFERROR('Historical FS'!C56/'Historical FS'!C$65,0) -> 0.21378068 | D34: =IFERROR('Historical FS'!D56/'Historical FS'!D$65,0) -> 0.15553479 | E34: =IFERROR('Historical FS'!E56/'Historical FS'!E$65,0) -> 0.15807775 | F34: =IFERROR('Historical FS'!F56/'Historical FS'!F$65,0) -> 0.12509938 | G34: =IFERROR('Historical FS'!G56/'Historical FS'!G$65,0) -> 0.23270552 | H34: =IFERROR('Historical FS'!H56/'Historical FS'!H$65,0) -> 0.14145262 | I34: =IFERROR('Historical FS'!I56/'Historical FS'!I$65,0) -> 0.165315 | J34: =IFERROR('Historical FS'!J56/'Historical FS'!J$65,0) -> 0.15343819 | ... L34: =IFERROR('Historical FS'!L56/'Historical FS'!L$65,0) -> 0.20457693
B35: ='Historical FS'!B57 -> Other Assets | C35: =IFERROR('Historical FS'!C57/'Historical FS'!C$65,0) -> 0.10617895 | D35: =IFERROR('Historical FS'!D57/'Historical FS'!D$65,0) -> 0.1229224 | E35: =IFERROR('Historical FS'!E57/'Historical FS'!E$65,0) -> 0.09058862 | F35: =IFERROR('Historical FS'!F57/'Historical FS'!F$65,0) -> 0.10774032 | G35: =IFERROR('Historical FS'!G57/'Historical FS'!G$65,0) -> 0.12603671 | H35: =IFERROR('Historical FS'!H57/'Historical FS'!H$65,0) -> 0.12529864 | I35: =IFERROR('Historical FS'!I57/'Historical FS'!I$65,0) -> 0.11777536 | J35: =IFERROR('Historical FS'!J57/'Historical FS'!J$65,0) -> 0.11944141 | ... L35: =IFERROR('Historical FS'!L57/'Historical FS'!L$65,0) -> 0.13583603
B36: ='Historical FS'!B58 -> Total Non Current Assets | C36: =IFERROR('Historical FS'!C58/'Historical FS'!C$65,0) -> 0.60703947 | D36: =IFERROR('Historical FS'!D58/'Historical FS'!D$65,0) -> 0.65171672 | E36: =IFERROR('Historical FS'!E58/'Historical FS'!E$65,0) -> 0.66138691 | F36: =IFERROR('Historical FS'!F58/'Historical FS'!F$65,0) -> 0.6301976 | G36: =IFERROR('Historical FS'!G58/'Historical FS'!G$65,0) -> 0.65554395 | H36: =IFERROR('Historical FS'!H58/'Historical FS'!H$65,0) -> 0.52571888 | I36: =IFERROR('Historical FS'!I58/'Historical FS'!I$65,0) -> 0.54648162 | J36: =IFERROR('Historical FS'!J58/'Historical FS'!J$65,0) -> 0.602135 | ... L36: =IFERROR('Historical FS'!L58/'Historical FS'!L$65,0) -> 0.67324512
B38: ='Historical FS'!B60 -> Receivables | C38: =IFERROR('Historical FS'!C60/'Historical FS'!C$65,0) -> 0.11661248 | D38: =IFERROR('Historical FS'!D60/'Historical FS'!D$65,0) -> 0.12574073 | E38: =IFERROR('Historical FS'!E60/'Historical FS'!E$65,0) -> 0.11738253 | F38: =IFERROR('Historical FS'!F60/'Historical FS'!F$65,0) -> 0.111242 | G38: =IFERROR('Historical FS'!G60/'Historical FS'!G$65,0) -> 0.12783722 | H38: =IFERROR('Historical FS'!H60/'Historical FS'!H$65,0) -> 0.16862826 | I38: =IFERROR('Historical FS'!I60/'Historical FS'!I$65,0) -> 0.17987046 | J38: =IFERROR('Historical FS'!J60/'Historical FS'!J$65,0) -> 0.16350917 | ... L38: =IFERROR('Historical FS'!L60/'Historical FS'!L$65,0) -> 0.12925729
B39: ='Historical FS'!B61 -> Inventory | C39: =IFERROR('Historical FS'!C61/'Historical FS'!C$65,0) -> 0.21176137 | D39: =IFERROR('Historical FS'!D61/'Historical FS'!D$65,0) -> 0.19314229 | E39: =IFERROR('Historical FS'!E61/'Historical FS'!E$65,0) -> 0.19385138 | F39: =IFERROR('Historical FS'!F61/'Historical FS'!F$65,0) -> 0.21005182 | G39: =IFERROR('Historical FS'!G61/'Historical FS'!G$65,0) -> 0.18661442 | H39: =IFERROR('Historical FS'!H61/'Historical FS'!H$65,0) -> 0.26800526 | I39: =IFERROR('Historical FS'!I61/'Historical FS'!I$65,0) -> 0.24091549 | J39: =IFERROR('Historical FS'!J61/'Historical FS'!J$65,0) -> 0.19810226 | ... L39: =IFERROR('Historical FS'!L61/'Historical FS'!L$65,0) -> 0.16639334
B40: ='Historical FS'!B62 -> Cash & Bank | C40: =IFERROR('Historical FS'!C62/'Historical FS'!C$65,0) -> 0.064586677 | D40: =IFERROR('Historical FS'!D62/'Historical FS'!D$65,0) -> 0.029400268 | E40: =IFERROR('Historical FS'!E62/'Historical FS'!E$65,0) -> 0.027379185 | F40: =IFERROR('Historical FS'!F62/'Historical FS'!F$65,0) -> 0.048508579 | G40: =IFERROR('Historical FS'!G62/'Historical FS'!G$65,0) -> 0.030004412 | H40: =IFERROR('Historical FS'!H62/'Historical FS'!H$65,0) -> 0.037647609 | I40: =IFERROR('Historical FS'!I62/'Historical FS'!I$65,0) -> 0.032732426 | J40: =IFERROR('Historical FS'!J62/'Historical FS'!J$65,0) -> 0.036253581 | ... L40: =IFERROR('Historical FS'!L62/'Historical FS'!L$65,0) -> 0.031104255
B41: ='Historical FS'!B63 -> Total Current Assets | C41: =IFERROR('Historical FS'!C63/'Historical FS'!C$65,0) -> 0.39296053 | D41: =IFERROR('Historical FS'!D63/'Historical FS'!D$65,0) -> 0.34828328 | E41: =IFERROR('Historical FS'!E63/'Historical FS'!E$65,0) -> 0.33861309 | F41: =IFERROR('Historical FS'!F63/'Historical FS'!F$65,0) -> 0.3698024 | G41: =IFERROR('Historical FS'!G63/'Historical FS'!G$65,0) -> 0.34445605 | H41: =IFERROR('Historical FS'!H63/'Historical FS'!H$65,0) -> 0.47428112 | I41: =IFERROR('Historical FS'!I63/'Historical FS'!I$65,0) -> 0.45351838 | J41: =IFERROR('Historical FS'!J63/'Historical FS'!J$65,0) -> 0.397865 | ... L41: =IFERROR('Historical FS'!L63/'Historical FS'!L$65,0) -> 0.32675488
